# Updated Implementation of ExtractContextFromException.create_llm_error_prompt function
class ExtractContextFromException:
    def create_llm_error_prompt(self, formatted_error: str) -> str:
        return f"""
The previous code generation attempt resulted in an error. Here are the details:

{formatted_error}

Please analyze this error and provide a corrected version of the code that addresses the issue.
"""

# Pytest Tests for ExtractContextFromException.create_llm_error_prompt function
import pytest
from unittest.mock import patch
from code_autoeval.llm_model.utils.extraction.extract_context_from_exception import ExtractContextFromException

@pytest.fixture
def extract_context():
    return ExtractContextFromException()

# Test normal use case with a non-empty formatted error string
def test_create_llm_error_prompt_normal(extract_context):
    formatted_error = "This is an example error message."
    result = extract_context.create_llm_error_prompt(formatted_error)
    assert "The previous code generation attempt resulted in an error." in result
    assert formatted_error in result
    assert "Please analyze this error and provide a corrected version of the code that addresses the issue." in result

# Test edge case with an empty formatted error string
def test_create_llm_error_prompt_empty(extract_context):
    formatted_error = ""
    result = extract_context.create_llm_error_prompt(formatted_error)
    assert "The previous code generation attempt resulted in an error." in result
    assert "Please analyze this error and provide a corrected version of the code that addresses the issue." in result

# Test for handling None input
def test_create_llm_error_prompt_none(extract_context):
    formatted_error = None
    with pytest.raises(TypeError):
        extract_context.create_llm_error_prompt(formatted_error)

# Test for ensuring the function is not asynchronous
@patch("code_autoeval.llm_model.utils.extraction.extract_context_from_exception.ExtractContextFromException.__init__", return_value=None)
def test_create_llm_error_prompt_is_not_async(mock_init):
    assert not asyncio.iscoroutinefunction(ExtractContextFromException.create_llm_error_prompt)

The previous code generation attempt resulted in an error. Here are the details:

This is an example error message.

Please analyze this error and provide a corrected version of the code that addresses the issue.